<?xml version="1.0"?>
<robot xmlns:xacro="http://www.ros.org/wiki/xacro" name="turtlebot3">

    <joint name="base_joint" type="fixed">
        <parent link="base_footprint"/>
        <child link="base_link"/>
        <origin xyz="0 0 0.01" rpy="0 0 0"/>
    </joint>


   <joint name="wheel_left_joint" type="continuous">
        <parent link="base_link"/>
        <child link="wheel_left_link"/>
        <origin xyz="0.0 0.144 0.023" rpy="-1.57 0 0"/>
        <axis xyz="0 0 1"/>
    </joint>

    <joint name="wheel_right_joint" type="continuous">
        <parent link="base_link"/>
        <child link="wheel_right_link"/>
        <origin xyz="0.0 -0.144 0.023" rpy="-1.57 0 0"/>
        <axis xyz="0 0 1"/>
    </joint>


    <joint name="caster_back_right_joint" type="fixed">
      <parent link="base_link"/>
      <child link="caster_back_right_link"/>
      <origin xyz="-0.177 -0.064 -0.004" rpy="-1.57 0 0"/>
    </joint>

    <joint name="caster_back_left_joint" type="fixed">
      <parent link="base_link"/>
      <child link="caster_back_left_link"/>
      <origin xyz="-0.177 0.064 -0.004" rpy="-1.57 0 0"/>
    </joint>


    <joint name="lidar_joint" type="fixed">
      <parent link="base_link"/>
      <child link="base_scan"/>
      <origin xyz="-0.064 0 0.122" rpy="0 0 0"/>
    </joint>

    <joint name="imu_joint" type="fixed">
        <parent link="base_link"/>
        <child link="imu_link"/>
        <origin xyz="0.0 0 0.068" rpy="0 0 0"/>
    </joint>

    <joint name="camera_joint" type="fixed">
        <parent link="base_link"/>
        <child link="camera_link"/>
        <origin xyz="0.073 0 0.084" rpy="0 0 0"/>
    </joint>

    <joint name="camera_optical_joint" type="fixed">
      <origin xyz="0.003 0 0.009" rpy="0 0 0"/>
      <parent link="camera_link"/>
      <child link="camera_link_optical"/>
    </joint>



</robot>